Workbook

Sheet Cover
A3: FUNCTION TESTCASE DOCUMENT
A6: Document name: [Project Code]_TestCase_SIT_Version_xx
A7: Version: [Enter version of document]
A8: Creator: [Enter account of creator] | D8: Create Date: [Enter create date]
A9: Reviewer: [Enter account of test leader] | D9: Review Date: [Enter duration testing date]
A12: REFERENCE DOCUMENTS
A14: No | B14: Document tyoe | C14: Document name | F14: Link
A22: HISTORY CHANGE
A24: No | B24: Date | C24: Version | D24: Category (*) | E24: Modified By | F24: Description
A30: ( *) A (Add), M (Modify), D (Delete)
A33: FUNCTIONS LIST
A35: No | B35: Function | D35: Tester | E35: Status | F35: Sheet Name

Sheet Report
B1: TEST SUMMARY REPORT
B2: [Project Name]
C4: Document name: [Enter document name]
C5: Version: [Enter version of document]
C6: Creator: [Enter account of creator] | E6: Create Date: [Enter create date]
C7: Test Leader: [Enter account of test leader] | E7: Test Date: [Enter duration testing (From date - To date)]
C8: Project Manager: [Enter account of PM]
C11: SIGNATURE
C13: Full name: | D13: Vũ Đình Đồng | F13: Signature
C14: Role: | D14: Test leader
C15: Date time: | D15: 01/10/2022
C17: Full name: | D17: Vũ Đình Đồng | F17: Signature
C18: Role: | D18: Test leader
C19: Date time: | D19: 01/10/2022
B23: 1. Test Tracking and Efficiency
B24: NO | C24: TEST TRACKING | D24: PERCENTAGE
B25: 1 | C25: Test Coverage | D25: =(G37+H37)/F37 -> 0.18128655
B26: 2 | C26: Passed Rate | D26: =(G37)/(G37+H37) -> 0.77419355
B27: 3 | C27: Failed Rate | D27: =(H37)/(G37+H37) -> 0.22580645
B28: 4 | C28: Fixed Defects | D28: =F46/D46 -> 0.5
B30: 2. Test Execution Status
B31: NO | C31: MODULE | D31: EXECUTION | E31: PASS RATE | F31: TOTAL TCs | G31: PASSED | H31: FAILED | I31: PENDING | J31: N/A
B32: 1 | C32: =QuanLyThuongHieu!$C$1 -> Quản lý thương hiệu | D32: =(G32+H32)/F32 -> 0.39726027 | E32: =G32/(G32+H32) -> 0.82758621 | F32: =SUM(G32:J32) -> 73 | G32: =QuanLyThuongHieu!H2 -> 24 | H32: =QuanLyThuongHieu!H3 -> 5 | I32: =QuanLyThuongHieu!H4 -> 0 | J32: =QuanLyThuongHieu!H5 -> 44
B33: 2 | C33: =QuanLyDanhMuc!C1 -> Quản lý danh mục | D33: =(G33+H33)/F33 -> 0.020408163 | E33: =G33/(G33+H33) -> 0 | F33: =SUM(G33:J33) -> 98 | G33: =QuanLyDanhMuc!H2 -> 0 | H33: =QuanLyDanhMuc!H3 -> 2 | I33: =QuanLyDanhMuc!H4 -> 0 | J33: =QuanLyDanhMuc!H5 -> 96
B34: 3
B35: 4
B36: 5
B37: TOTAL | F37: =SUM(F32:F36) -> 171 | G37: =SUM(G32:G36) -> 24 | H37: =SUM(H32:H36) -> 7 | I37: =SUM(I32:I36) -> 0 | J37: =SUM(J32:J36) -> 140
B39: 3. Bug Status
B40: =B31 -> NO | C40: =C31 -> MODULE | D40: TOTAL | E40: FIX RATE | F40: DONE | G40: OPEN | H40: PENDING | I40: REJECTED
B41: =B32 -> 1 | C41: =QuanLyThuongHieu!$C$1 -> Quản lý thương hiệu | D41: =SUM(F41:H41) -> 0 | E41: =F41/D41 -> #DIV/0! | F41: =QuanLyThuongHieu!J2 -> 0 | G41: =QuanLyThuongHieu!J3 -> 0 | H41: =QuanLyThuongHieu!J4 -> 0 | I41: =QuanLyThuongHieu!J5 -> 0
B42: =B33 -> 2 | C42: =QuanLyDanhMuc!C1 -> Quản lý danh mục | D42: =SUM(F42:H42) -> 2 | E42: =F42/D42 -> 0.5 | F42: =QuanLyDanhMuc!J2 -> 1 | G42: =QuanLyDanhMuc!J2 -> 1 | H42: =QuanLyDanhMuc!J3 -> 0 | I42: =QuanLyDanhMuc!J4 -> 0
B43: =B34 -> 3
B44: =B35 -> 4
B45: =B36 -> 5
B46: =B37 -> TOTAL | D46: =SUM(D41:D45) -> 2 | E46: =SUM(E41:E45) -> #DIV/0! | F46: =SUM(F41:F45) -> 1 | G46: =SUM(G41:G45) -> 1 | H46: =SUM(H41:H45) -> 0 | I46: =SUM(I41:I45) -> 0
B49: 5. Testing Chart

Sheet Glossary
A1: Trạng thái | B1: Note | D1: TEST STATUS | F1: BUG STATUS | H1: BUG TYPE | J1: PRIORITY | L1: SEVERITY
A2: NOT READY | B2: Chưa bắt đầu test | D2: Passed | F2: Done | H2: Business | J2: Highest | L2: Blocked
A3: IN-PROGRESS | B3: Đang test chưa hết round 1 | D3: Failed | F3: Open | H3: Validate | J3: High | L3: Critical
A4: FIXBUG | B4: Hết round 1, có bug đang chờ fix | D4: Pending | F4: Pending | H4: UI/UX | J4: Medium | L4: Major
A5: PASSED INTERNAL | B5: Đã test xong và fix xong bug | D5: N/A | F5: Rejected | J5: Low | L5: Minor
A6: PENDING | B6: Không test tiếp được do có blocker
A7: READY FOR TEST | B7: Sẵn sàng để test internal
A8: IN UAT | B8: Đã lên UAT
A9: FAILED UAT | B9: Fail trên UAT
A10: PASSED UAT | B10: Pass trên UAT
A11: CREATE T/C | B11: Đang tạo test case

Sheet QuanLyThuongHieu
B1: Module Name | C1: Quản lý thương hiệu | G1: Kết quả test | I1: Trạng thái lỗi
B2: Module Code | C2: Brand | G2: =Glossary!D2 -> Passed | H2: =COUNTIF($H$10:H581,G2) -> 24 | I2: =Glossary!F2 -> Done | J2: =COUNTIF($I$10:I581,I2) -> 0
B3: Total Testcases | C3: =COUNTA(G10:G581) -> 73 | G3: =Glossary!D3 -> Failed | H3: =COUNTIF($H$10:H582,G3) -> 5 | I3: =Glossary!F3 -> Open | J3: =COUNTIF($I$10:I582,I3) -> 0
B4: Coverage | C4: =($H$2+$H$3)/$C$3 -> 0.39726027 | G4: =Glossary!D4 -> Pending | H4: =COUNTIF($H$10:H583,G4) -> 0 | I4: =Glossary!F4 -> Pending | J4: =COUNTIF($I$10:I583,I4) -> 0
B5: Creator | G5: =Glossary!D5 -> N/A | H5: =COUNTIF($H$10:H584,G5) -> 44 | I5: =Glossary!F5 -> Rejected | J5: =COUNTIF($I$10:I584,I5) -> 0
A7: TC_ID | B7: Mục đích kiểm thử | C7: Kịch bản | D7: Trường hợp kiểm thử | E7: Dữ liệu | F7: Bước thực hiện | G7: Kết quả mong muốn | H7: Kết quả | I7: Trạng thái lỗi | J7: Ghi chú
B8: Pre-condition: Đăng nhập hệ thống với tài khoản có quyền
B9: Danh sách thương hiệu
B10: Kiểm tra giao diện
A11: =IF(G11="","",$C$2&"-"&SUBTOTAL(3,$G$10:G11)) -> Brand-1 | B11: Kiểm tra giao diện chung của màn hình chức năng | C11: Kiểm tra giao diện so với thiết kế | D11: Kiểm tra giao diện so với thiết kế | F11: 1. Truy cập màn hình Quản lý Thương hiệu 2. Kiểm tra giao diện màn hình chức năng so với thiết kế | G11: 2. Hiển thị giao diện màn hình chức năng đúng với thiết kế Figma: - Title: Quản lý thương hiệu - Button: Thêm thương hiệu - Textbox tìm kiếm - Gird danh sách thương hiệu | H11: Passed
A12: =IF(G12="","",$C$2&"-"&SUBTOTAL(3,$G$10:G12)) -> Brand-2 | G12: 2. Các trường thông tin hiển thị đúng chính tả | H12: Passed
A13: =IF(G13="","",$C$2&"-"&SUBTOTAL(3,$G$10:G13)) -> Brand-3 | G13: 2. Các trường thông tin hiển thị đúng layout, căn chỉnh thẳng hàng, không bị xô lệch | H13: Passed
A14: =IF(G14="","",$C$2&"-"&SUBTOTAL(3,$G$10:G14)) -> Brand-4 | G14: 2. Các trường thông tin hiển thị đúng stype, color, font size | H14: Passed
A15: =IF(G15="","",$C$2&"-"&SUBTOTAL(3,$G$10:G15)) -> Brand-5 | C15: Kiểm tra hiển thị danh sách thương hiệu | D15: Không có dữ liệu thương hiệu | F15: Tại màn hình quản lý thương hiệu 1. Kiểm tra gird thương hiệu trên màn hình | G15: 1. Hiển thị thông báo "Không có thương hiệu phù hợp" | H15: Failed | J15: Không tìm thấy thương hiệu phù hợp
A16: =IF(G16="","",$C$2&"-"&SUBTOTAL(3,$G$10:G16)) -> Brand-6 | D16: Có dữ liệu thương hiệu | F16: Tại màn hình quản lý thương hiệu 1. Kiểm tra gird thương hiệu trên màn hình | G16: 1. Hiển thị card thông tin thương hiệu gồm - icon thương hiệu - Tên thương hiệu - Số lượng sản phẩm gắn với thương hiệu - icon edit - icon delete | H16: Failed | J16: Số lượng ko hiển thị đúng
A17: =IF(G17="","",$C$2&"-"&SUBTOTAL(3,$G$10:G17)) -> Brand-7 | G17: 1. Gird card hiển thị 3 cột trên dòng | H17: Passed
A18: =IF(G18="","",$C$2&"-"&SUBTOTAL(3,$G$10:G18)) -> Brand-8 | B18: Kiểm tra giao diện tìm kiếm | C18: Kiểm tra giao diện tìm kiếm | D18: Kiểm tra giao diện tìm kiếm | F18: Tại màn hình quản lý thương hiệu 1. Kiểm tra trường Tìm kiếm | G18: 1. Mặc định trường textbox Trống | H18: Passed
A19: =IF(G19="","",$C$2&"-"&SUBTOTAL(3,$G$10:G19)) -> Brand-9 | G19: 1. Hiển thị place holder text "Tìm kiếm theo tên thương hiệu" | H19: Passed
A20: =IF(G20="","",$C$2&"-"&SUBTOTAL(3,$G$10:G20)) | B20: Kiểm tra validate trường thông tin
A21: =IF(G21="","",$C$2&"-"&SUBTOTAL(3,$G$10:G21)) -> Brand-10 | B21: Kiểm tra validate trường Tìm kiếm theo tên thương hiệu | C21: Nhập thông tin hợp lệ | D21: Nhập thương hiệu đang hoạt động | F21: Tại màn hình quản lý thương hiệu 1. Nhập thông tin tìm kiếm như kịch bản test 2. Kiểm tra kết quả tìm kiếm | G21: 2. Cho phép nhập thông tin, thực hiện tìm kiếm | H21: Passed
A22: =IF(G22="","",$C$2&"-"&SUBTOTAL(3,$G$10:G22)) -> Brand-11 | D22: Nhập thương hiệu đã bị xóa | G22: 2. Cho phép nhập thông tin, thực hiện tìm kiếm | H22: Passed
A23: =IF(G23="","",$C$2&"-"&SUBTOTAL(3,$G$10:G23)) -> Brand-12 | C23: Nhập thông tin không hợp lệ | D23: Nhập thương hiệu không tồn tại | F23: Tại màn hình quản lý thương hiệu 1. Nhập thông tin tìm kiếm như kịch bản test 2. Kiểm tra kết quả tìm kiếm | G23: 2. Cho phép nhập thông tin, thực hiện tìm kiếm | H23: Passed
A24: =IF(G24="","",$C$2&"-"&SUBTOTAL(3,$G$10:G24)) | B24: Kiểm tra chức năng
A25: =IF(G25="","",$C$2&"-"&SUBTOTAL(3,$G$10:G25)) -> Brand-13 | B25: Kiểm tra chức năng tìm kiếm | C25: Tìm kiếm với keyword tồn tại | D25: Nhập thương hiệu đang hoạt động | F25: Tại màn hình quản lý thương hiệu 1. Nhập thông tin tìm kiếm như kịch bản test 2. Kiểm tra kết quả tìm kiếm | G25: 2. Hiển thị danh sách thương hiệu theo keyword | H25: Passed
A26: =IF(G26="","",$C$2&"-"&SUBTOTAL(3,$G$10:G26)) -> Brand-14 | G26: 2. Hiển thị đúng dữ liệu trong db SQL: SELECT * FROM Brands WHERE name = '' | H26: Passed
A27: =IF(G27="","",$C$2&"-"&SUBTOTAL(3,$G$10:G27)) -> Brand-15 | D27: Nhập thương hiệu đã bị xóa | F27: Tại màn hình quản lý thương hiệu 1. Nhập thông tin tìm kiếm như kịch bản test 2. Kiểm tra kết quả tìm kiếm | G27: 2. Báo lỗi "Không tìm thấy thương hiệu phù hợp" | H27: Passed
A28: =IF(G28="","",$C$2&"-"&SUBTOTAL(3,$G$10:G28)) -> Brand-16 | C28: Tìm kiếm với keyword không tồn tại | D28: Nhập thương hiệu không tồn tại | F28: Tại màn hình quản lý thương hiệu 1. Nhập thông tin tìm kiếm như kịch bản test 2. Kiểm tra kết quả tìm kiếm | G28: 2. Báo lỗi "Không tìm thấy thương hiệu phù hợp" | H28: Passed
A29: =IF(G29="","",$C$2&"-"&SUBTOTAL(3,$G$10:G29)) -> Brand-17 | B29: Kiểm tra chức năng các button | C29: Kiểm tra chức năng các button | D29: Kiểm tra button Thêm thương hiệu | F29: Tại màn hình quản lý thương hiệu 1. Click button Thêm mới 2. Kiểm tra thao tác | G29: 2. Hiển thị popup Thêm mới | H29: Passed
A30: =IF(G30="","",$C$2&"-"&SUBTOTAL(3,$G$10:G30)) -> Brand-18 | D30: Kiểm tra icon edit | F30: Tại màn hình quản lý thương hiệu 1. Click icon edit trên bản ghi 2. Kiểm tra thao tác | G30: 2. Hiển thị popup Chỉnh sửa | H30: Passed
A31: =IF(G31="","",$C$2&"-"&SUBTOTAL(3,$G$10:G31)) -> Brand-19 | D31: Kiểm tra icon delete | F31: Tại màn hình quản lý thương hiệu 1. Click icon delete trên bản ghi 2. Kiểm tra thao tác | G31: 2. Hiển thị Dialog Xóa | H31: Passed
A32: =IF(G32="","",$C$2&"-"&SUBTOTAL(3,$G$10:G32)) | B32: Thêm mới thương hiệu
A33: =IF(G33="","",$C$2&"-"&SUBTOTAL(3,$G$10:G33)) | B33: Kiểm tra giao diện
A34: =IF(G34="","",$C$2&"-"&SUBTOTAL(3,$G$10:G34)) -> Brand-20 | B34: Kiểm tra giao diện chung của màn hình chức năng | C34: Kiểm tra giao diện so với thiết kế | D34: Kiểm tra giao diện so với thiết kế | F34: Tại màn hình quản lý thương hiệu 1. Click button "Thêm thương hiệu" 2. Kiểm tra giao diện màn hình chức năng so với thiết kế | G34: 2. Hiển thị giao diện màn hình chức năng đúng với thiết kế Figma: - Title: Thêm thương hiệu - Button: Hủy, Lưu - Textbox Tên thương hiệu * | H34: Passed
A35: =IF(G35="","",$C$2&"-"&SUBTOTAL(3,$G$10:G35)) -> Brand-21 | G35: 2. Các trường thông tin hiển thị đúng chính tả | H35: Passed
A36: =IF(G36="","",$C$2&"-"&SUBTOTAL(3,$G$10:G36)) -> Brand-22 | G36: 2. Các trường thông tin hiển thị đúng layout, căn chỉnh thẳng hàng, không bị xô lệch | H36: Passed
A37: =IF(G37="","",$C$2&"-"&SUBTOTAL(3,$G$10:G37)) -> Brand-23 | G37: 2. Các trường thông tin hiển thị đúng stype, color, font size | H37: Passed
A38: =IF(G38="","",$C$2&"-"&SUBTOTAL(3,$G$10:G38)) -> Brand-24 | G38: 2. Error message được hiển thị inline, màu đỏ | H38: Failed | J38: Bắn cả response message lên giao diện
A39: =IF(G39="","",$C$2&"-"&SUBTOTAL(3,$G$10:G39)) -> Brand-25 | C39: Kiểm tra giá trị mặc định | D39: Kiểm tra giá trị trường Tên thương hiệu | F39: Tại màn hình thêm mới thương hiệu 1. Kiểm tra giá trị mặc định trường Tên thương hiệu | G39: 1. Tên thương hiệu mặc định trống | H39: Passed
A40: =IF(G40="","",$C$2&"-"&SUBTOTAL(3,$G$10:G40)) -> Brand-26 | G40: 1. Hiển thị place holder text "Nhập tên thương hiệu" | H40: Passed
A41: =IF(G41="","",$C$2&"-"&SUBTOTAL(3,$G$10:G41)) | B41: Kiểm tra validate trường thông tin
...

Sheet QuanLyDanhMuc
B1: Module Name | C1: Quản lý danh mục | G1: Kết quả test | I1: Trạng thái lỗi
B2: Module Code | C2: Categories | G2: =Glossary!D2 -> Passed | H2: =COUNTIF($H$10:H606,G2) -> 0 | I2: =Glossary!F2 -> Done | J2: =COUNTIF($I$10:I606,I2) -> 1
B3: Total Testcases | C3: =COUNTA(G10:G606) -> 98 | G3: =Glossary!D3 -> Failed | H3: =COUNTIF($H$10:H607,G3) -> 2 | I3: =Glossary!F3 -> Open | J3: =COUNTIF($I$10:I607,I3) -> 0
B4: Coverage | C4: =($H$2+$H$3)/$C$3 -> 0.020408163 | G4: =Glossary!D4 -> Pending | H4: =COUNTIF($H$10:H608,G4) -> 0 | I4: =Glossary!F4 -> Pending | J4: =COUNTIF($I$10:I608,I4) -> 0
B5: Creator | G5: =Glossary!D5 -> N/A | H5: =COUNTIF($H$10:H609,G5) -> 96 | I5: =Glossary!F5 -> Rejected | J5: =COUNTIF($I$10:I609,I5) -> 0
A7: TC_ID | B7: Mục đích kiểm thử | C7: Kịch bản | D7: Trường hợp kiểm thử | E7: Dữ liệu | F7: Bước thực hiện | G7: Kết quả mong muốn | H7: Kết quả | I7: Trạng thái lỗi | J7: Ghi chú
B8: Pre-condition: Đăng nhập hệ thống với tài khoản có quyền
B9: Danh sách danh mục
B10: Kiểm tra giao diện
A11: =IF(G11="","",$C$2&"-"&SUBTOTAL(3,$G$10:G11)) -> Categories-1 | B11: Kiểm tra giao diện chung của màn hình chức năng | C11: Kiểm tra giao diện so với thiết kế | D11: Kiểm tra giao diện so với thiết kế | F11: 1. Truy cập màn hình Quản lý danh mục 2. Kiểm tra giao diện màn hình chức năng so với thiết kế | G11: 2. Hiển thị giao diện màn hình chức năng đúng với thiết kế Figma: - Title: Quản lý danh mục - Button: Thêm danh mục - Textbox tìm kiếm - Gird danh sách danh mục | H11: N/A
A12: =IF(G12="","",$C$2&"-"&SUBTOTAL(3,$G$10:G12)) -> Categories-2 | G12: 2. Các trường thông tin hiển thị đúng chính tả | H12: N/A
A13: =IF(G13="","",$C$2&"-"&SUBTOTAL(3,$G$10:G13)) -> Categories-3 | G13: 2. Các trường thông tin hiển thị đúng layout, căn chỉnh thẳng hàng, không bị xô lệch | H13: N/A
A14: =IF(G14="","",$C$2&"-"&SUBTOTAL(3,$G$10:G14)) -> Categories-4 | G14: 2. Các trường thông tin hiển thị đúng stype, color, font size | H14: N/A
A15: =IF(G15="","",$C$2&"-"&SUBTOTAL(3,$G$10:G15)) -> Categories-5 | C15: Kiểm tra hiển thị danh sách danh mục | D15: Không có dữ liệu danh mục | F15: Tại màn hình quản lý danh mục 1. Kiểm tra gird danh mục trên màn hình | G15: 1. Hiển thị thông báo "Không có danh mục phù hợp" | H15: N/A
A16: =IF(G16="","",$C$2&"-"&SUBTOTAL(3,$G$10:G16)) -> Categories-6 | D16: Có dữ liệu danh mục | F16: Tại màn hình quản lý danh mục 1. Kiểm tra gird danh mục trên màn hình | G16: 1. Hiển thị card thông tin danh mục gồm - icon danh mục - Tên danh mục - Mô tả - Trạng thái - icon edit - icon delete | H16: N/A
A17: =IF(G17="","",$C$2&"-"&SUBTOTAL(3,$G$10:G17)) -> Categories-7 | G17: 1. Gird card hiển thị 3 cột trên dòng | H17: N/A
A18: =IF(G18="","",$C$2&"-"&SUBTOTAL(3,$G$10:G18)) -> Categories-8 | B18: Kiểm tra giao diện tìm kiếm | C18: Kiểm tra giao diện tìm kiếm | D18: Kiểm tra giao diện tìm kiếm | F18: Tại màn hình quản lý danh mục 1. Kiểm tra trường Tìm kiếm | G18: 1. Mặc định trường textbox Trống | H18: N/A
A19: =IF(G19="","",$C$2&"-"&SUBTOTAL(3,$G$10:G19)) -> Categories-9 | G19: 1. Hiển thị place holder text "Tìm kiếm theo tên hoặc mô tả danh mục" | H19: N/A
A20: =IF(G20="","",$C$2&"-"&SUBTOTAL(3,$G$10:G20)) | B20: Kiểm tra validate trường thông tin
A21: =IF(G21="","",$C$2&"-"&SUBTOTAL(3,$G$10:G21)) -> Categories-10 | B21: Kiểm tra validate trường Tìm kiếm theo tên danh mục | C21: Nhập thông tin hợp lệ | D21: Nhập danh mục đang hoạt động | F21: Tại màn hình quản lý danh mục 1. Nhập thông tin tìm kiếm như kịch bản test 2. Kiểm tra kết quả tìm kiếm | G21: 2. Cho phép nhập thông tin, thực hiện tìm kiếm | H21: N/A
A22: =IF(G22="","",$C$2&"-"&SUBTOTAL(3,$G$10:G22)) -> Categories-11 | D22: Nhập danh mục không hoạt động | F22: Tại màn hình quản lý danh mục 1. Nhập thông tin tìm kiếm như kịch bản test 2. Kiểm tra kết quả tìm kiếm | G22: 2. Cho phép nhập thông tin, thực hiện tìm kiếm | H22: N/A
A23: =IF(G23="","",$C$2&"-"&SUBTOTAL(3,$G$10:G23)) -> Categories-12 | D23: Nhập danh mục đã bị xóa | F23: Tại màn hình quản lý danh mục 1. Nhập thông tin tìm kiếm như kịch bản test 2. Kiểm tra kết quả tìm kiếm | G23: 2. Cho phép nhập thông tin, thực hiện tìm kiếm | H23: N/A
A24: =IF(G24="","",$C$2&"-"&SUBTOTAL(3,$G$10:G24)) -> Categories-13 | C24: Nhập thông tin không hợp lệ | D24: Nhập danh mục không tồn tại | F24: Tại màn hình quản lý danh mục 1. Nhập thông tin tìm kiếm như kịch bản test 2. Kiểm tra kết quả tìm kiếm | G24: 2. Cho phép nhập thông tin, thực hiện tìm kiếm | H24: N/A
A25: =IF(G25="","",$C$2&"-"&SUBTOTAL(3,$G$10:G25)) | B25: Kiểm tra chức năng
A26: =IF(G26="","",$C$2&"-"&SUBTOTAL(3,$G$10:G26)) -> Categories-14 | B26: Kiểm tra chức năng tìm kiếm | C26: Tìm kiếm với keyword tồn tại | D26: Nhập danh mục đang hoạt động | F26: Tại màn hình quản lý danh mục 1. Nhập thông tin tìm kiếm như kịch bản test 2. Kiểm tra kết quả tìm kiếm | G26: 2. Hiển thị danh sách danh mục theo keyword | H26: N/A
A27: =IF(G27="","",$C$2&"-"&SUBTOTAL(3,$G$10:G27)) -> Categories-15 | G27: 2. Hiển thị đúng dữ liệu trong db SQL: SELECT * FROM categories WHERE name = '' OR description='' AND active = true AND delete_at is null | H27: N/A
A28: =IF(G28="","",$C$2&"-"&SUBTOTAL(3,$G$10:G28)) -> Categories-16 | D28: Nhập danh mục không hoạt động | F28: Tại màn hình quản lý danh mục 1. Nhập thông tin tìm kiếm như kịch bản test 2. Kiểm tra kết quả tìm kiếm | G28: 2. Hiển thị danh sách danh mục theo keyword | H28: N/A
A29: =IF(G29="","",$C$2&"-"&SUBTOTAL(3,$G$10:G29)) -> Categories-17 | G29: 2. Hiển thị đúng dữ liệu trong db SQL: SELECT * FROM categories WHERE name = '' AND active = false AND delete_at is null | H29: N/A
A30: =IF(G30="","",$C$2&"-"&SUBTOTAL(3,$G$10:G30)) -> Categories-18 | D30: Nhập danh mục đã bị xóa | F30: Tại màn hình quản lý danh mục 1. Nhập thông tin tìm kiếm như kịch bản test 2. Kiểm tra kết quả tìm kiếm | G30: 2. Báo lỗi "Không tìm thấy danh mục phù hợp" | H30: Failed | I30: Done | J30: QAT-251
A31: =IF(G31="","",$C$2&"-"&SUBTOTAL(3,$G$10:G31)) -> Categories-19 | G31: 2. Hiển thị đúng dữ liệu trong db SQL: SELECT * FROM categories WHERE name = '' AND active = false AND delete_at not null | H31: N/A
A32: =IF(G32="","",$C$2&"-"&SUBTOTAL(3,$G$10:G32)) -> Categories-20 | C32: Tìm kiếm với keyword không tồn tại | D32: Nhập danh mục không tồn tại | F32: Tại màn hình quản lý danh mục 1. Nhập thông tin tìm kiếm như kịch bản test 2. Kiểm tra kết quả tìm kiếm | G32: 2. Báo lỗi "Không tìm thấy danh mục phù hợp" | H32: N/A
A33: =IF(G33="","",$C$2&"-"&SUBTOTAL(3,$G$10:G33)) -> Categories-21 | B33: Kiểm tra chức năng các button | C33: Kiểm tra chức năng các button | D33: Kiểm tra button Thêm danh mục | F33: Tại màn hình quản lý danh mục 1. Click button Thêm mới 2. Kiểm tra thao tác | G33: 2. Hiển thị popup Thêm mới | H33: N/A
A34: =IF(G34="","",$C$2&"-"&SUBTOTAL(3,$G$10:G34)) -> Categories-22 | D34: Kiểm tra icon edit | F34: Tại màn hình quản lý danh mục 1. Click icon edit trên bản ghi 2. Kiểm tra thao tác | G34: 2. Hiển thị popup Chỉnh sửa | H34: N/A
A35: =IF(G35="","",$C$2&"-"&SUBTOTAL(3,$G$10:G35)) -> Categories-23 | D35: Kiểm tra icon delete | F35: Tại màn hình quản lý danh mục 1. Click icon delete trên bản ghi 2. Kiểm tra thao tác | G35: 2. Hiển thị Dialog Xóa | H35: N/A
A36: =IF(G36="","",$C$2&"-"&SUBTOTAL(3,$G$10:G36)) | B36: Thêm mới danh mục
A37: =IF(G37="","",$C$2&"-"&SUBTOTAL(3,$G$10:G37)) | B37: Kiểm tra giao diện
A38: =IF(G38="","",$C$2&"-"&SUBTOTAL(3,$G$10:G38)) -> Categories-24 | B38: Kiểm tra giao diện chung của màn hình chức năng | C38: Kiểm tra giao diện so với thiết kế | D38: Kiểm tra giao diện so với thiết kế | F38: Tại màn hình quản lý danh mục 1. Click button "Thêm danh mục" 2. Kiểm tra giao diện màn hình chức năng so với thiết kế | G38: 2. Hiển thị giao diện màn hình chức năng đúng với thiết kế Figma: - Title: Thêm danh mục - Button: Hủy, Lưu - Textbox Tên danh mục * - Text Area Mô tả danh mục - Upload ảnh - Checkbox Hoạt động | H38: N/A
A39: =IF(G39="","",$C$2&"-"&SUBTOTAL(3,$G$10:G39)) -> Categories-25 | G39: 2. Các trường thông tin hiển thị đúng chính tả | H39: N/A
A40: =IF(G40="","",$C$2&"-"&SUBTOTAL(3,$G$10:G40)) -> Categories-26 | G40: 2. Các trường thông tin hiển thị đúng layout, căn chỉnh thẳng hàng, không bị xô lệch | H40: N/A
A41: =IF(G41="","",$C$2&"-"&SUBTOTAL(3,$G$10:G41)) -> Categories-27 | G41: 2. Các trường thông tin hiển thị đúng stype, color, font size | H41: N/A
...

Sheet Bản sao của QuanLyDanhMuc
B1: Module Name | C1: Quản lý giỏ hàng | G1: Kết quả test | I1: Trạng thái lỗi
B2: Module Code | C2: Categories | G2: =Glossary!D2 -> Passed | H2: =COUNTIF($H$10:H625,G2) -> 0 | I2: =Glossary!F2 -> Done | J2: =COUNTIF($I$10:I625,I2) -> 0
B3: Total Testcases | C3: =COUNTA(G10:G625) -> 9 | G3: =Glossary!D3 -> Failed | H3: =COUNTIF($H$10:H626,G3) -> 0 | I3: =Glossary!F3 -> Open | J3: =COUNTIF($I$10:I626,I3) -> 0
B4: Coverage | C4: =($H$2+$H$3)/$C$3 -> 0 | G4: =Glossary!D4 -> Pending | H4: =COUNTIF($H$10:H627,G4) -> 0 | I4: =Glossary!F4 -> Pending | J4: =COUNTIF($I$10:I627,I4) -> 0
B5: Creator | G5: =Glossary!D5 -> N/A | H5: =COUNTIF($H$10:H628,G5) -> 98 | I5: =Glossary!F5 -> Rejected | J5: =COUNTIF($I$10:I628,I5) -> 0
A7: TC_ID | B7: Mục đích kiểm thử | C7: Kịch bản | D7: Trường hợp kiểm thử | E7: Dữ liệu | F7: Bước thực hiện | G7: Kết quả mong muốn | H7: Kết quả | I7: Trạng thái lỗi | J7: Ghi chú
B8: Pre-condition: Đăng nhập hệ thống với tài khoản có quyền
B9: Danh sách giỏ hàng
B10: Kiểm tra giao diện
A11: =IF(G11="","",$C$2&"-"&SUBTOTAL(3,$G$10:G11)) -> Categories-1 | B11: Kiểm tra giao diện chức năng | C11: Kiểm tra giao diện với thiết kế | D11: Kiểm tra giao diện với thiết kế | F11: 1. Truy cập màn hình quản lý giỏ hàng 2. Kiểm tra giao diện màn hình danh sách giỏ hàng | G11: 2. Giỏ hàng hiển thị đúng với design Figma: | H11: N/A
A12: =IF(G12="","",$C$2&"-"&SUBTOTAL(3,$G$10:G12)) | H12: N/A
A13: =IF(G13="","",$C$2&"-"&SUBTOTAL(3,$G$10:G13)) | H13: N/A
A14: =IF(G14="","",$C$2&"-"&SUBTOTAL(3,$G$10:G14)) | H14: N/A
A15: =IF(G15="","",$C$2&"-"&SUBTOTAL(3,$G$10:G15)) | H15: N/A | J15: Không tìm thấy danh mục phù hợp
A16: =IF(G16="","",$C$2&"-"&SUBTOTAL(3,$G$10:G16)) | H16: N/A | J16: Số lượng ko hiển thị đúng
A17: =IF(G17="","",$C$2&"-"&SUBTOTAL(3,$G$10:G17)) | H17: N/A
A18: =IF(G18="","",$C$2&"-"&SUBTOTAL(3,$G$10:G18)) | H18: N/A
A19: =IF(G19="","",$C$2&"-"&SUBTOTAL(3,$G$10:G19)) | H19: N/A
A20: =IF(G20="","",$C$2&"-"&SUBTOTAL(3,$G$10:G20)) | B20: Validate
A21: =IF(G21="","",$C$2&"-"&SUBTOTAL(3,$G$10:G21)) | B21: Tên | C21: Hợp lệ | D21: Không trống | H21: N/A
D22: Nhập 99 ký tự (<100 ký tự)
D23: Nhập 100 ký tự
D24: 5345612%$!52647 | F24: 5345612%$!52647
C27: Không hợp lệ
B28: Mã
A29: =IF(G29="","",$C$2&"-"&SUBTOTAL(3,$G$10:G29)) | B29: Giá | H29: N/A
A30: =IF(G30="","",$C$2&"-"&SUBTOTAL(3,$G$10:G30)) | H30: N/A
A31: =IF(G31="","",$C$2&"-"&SUBTOTAL(3,$G$10:G31)) | H31: N/A
B32: FUnction | C32: Đại lý
A33: =IF(G33="","",$C$2&"-"&SUBTOTAL(3,$G$10:G33)) | B33: Chi tiết | C33: TTC
A34: =IF(G34="","",$C$2&"-"&SUBTOTAL(3,$G$10:G34)) | C34: Đại lý | H34: N/A
A35: =IF(G35="","",$C$2&"-"&SUBTOTAL(3,$G$10:G35)) | B35: Xoá | H35: N/A
H36: N/A
A37: =IF(G37="","",$C$2&"-"&SUBTOTAL(3,$G$10:G37)) | H37: N/A
A38: =IF(G38="","",$C$2&"-"&SUBTOTAL(3,$G$10:G38)) | H38: N/A
H39: N/A
A40: =IF(G40="","",$C$2&"-"&SUBTOTAL(3,$G$10:G40)) | H40: N/A
A41: =IF(G41="","",$C$2&"-"&SUBTOTAL(3,$G$10:G41)) | H41: N/A
A42: =IF(G42="","",$C$2&"-"&SUBTOTAL(3,$G$10:G42)) | H42: N/A
A43: =IF(G43="","",$C$2&"-"&SUBTOTAL(3,$G$10:G43)) | H43: N/A
...

Sheet Design
A1: Loại khuyến mại | B1: https://app.mindmup.com/map/_free/2026/04/82ee17e038d411f182adb14e9429b705
A2: Giá trị KM | C2: Phân vùng tương đương
A3: Đơn hàng tối thiểu | C3: Giá trị biên
A4: TG Bắt đầu
A5: TG Kết thúc
A6: KÍch hoạt
A8: Bảng quyết định
B9: Loại khuyến mại | C9: Giá trị KM | D9: Đơn hàng tối thiểu | E9: TG Bắt đầu | F9: TG Kết thúc | G9: KÍch hoạt | H9: KQ Mong muống
A10: TC1 | B10: % | C10: Bằng tổng HĐ | D10: 100đ | E10: T | F10: T | G10: T
A11: TC2 | B11: % | C11: Bằng tổng HĐ | D11: >100đ
A12: TC3 | C12: < tổng HĐ | D12: 100đ
A13: TC4 | D13: >100đ
A14: TC5 | B14: Số tiền | C14: Bằng tổng HĐ | D14: 100đ | E14: T | F14: T | G14: T
A15: TC6 | D15: >100đ
A16: TC7 | C16: < tổng HĐ | D16: 100đ
A17: TC8 | D17: >100đ
A18: TC9 | B18: MP Vận chuyển | C18: Bằng tổng HĐ | D18: 100đ | E18: T | F18: T | G18: T
A19: TC10 | D19: >100đ
A20: TC11 | C20: < tổng HĐ | D20: 100đ
A21: TC12 | D21: >100đ
A25: Danh sách danh mục
A26: GUI | B26: API ??? | C26: DB.Tables (Categories)
A27: Tên | C27: name
A28: Mô tả | C28: description
A29: Trạng thái | C29: active
A30: ẢNh | C30: image_url
C31: id
C33: TC1
A34: Loại khuyến mại | B34: % | C34: T % | D34: T % | E34: T %
A35: Giá trị KM | B35: 0.1 | C35: T 10% | D35: T 10% | E35: F 10%
A36: Sồ tiền KM tối đa | B36: 20k | C36: 20k
A37: Đơn hàng tối thiểu | B37: 500k | C37: T 500k | D37: F 499k | E37: F 499k
C38: 450k | D38: 499k
B41: Kích hoạt | C41: T | D41: T | E41: T | F41: F | G41: F
B42: Bắt đầu | C42: T | D42: F | E42: T | F42: T | G42: T
B43: Kết thúc | C43: T | D43: T | E43: F | F43: T | G43: T
C44: Use | D44: Not Use | E44: U | F44: Not | G44: Not
A49: {
A50: content: [
A51: {
...

Sheet Trang tính5
A4: id: "11111111-0003-0003-0003-000000000003",
A6: name: "Canon EOS 5D Mark IV Body",
A11: inStock: true,
A13: id: 1,
A15: imageUrl: "https://placehold.co/400x300/png?text=DSLR",
A20: id: 1,
A27: id: "11111111-0004-0004-0004-000000000004",
A34: inStock: true,
A36: id: 1,
A38: imageUrl: "https://placehold.co/400x300/png?text=DSLR",
A43: id: 2,
A50: id: "11111111-0005-0005-0005-000000000005",
... A710: id: 1,
